#VRML_SIM R2019a utf8
WorldInfo {
}
Viewpoint {
  orientation -0.0914611660756962 0.9946928371040111 -0.04712764490240282 6.131090628901019
  position 0.07604663232503102 0.036226011469302856 0.8590047615433163
}
TexturedBackground {
}
TexturedBackgroundLight {
}
Floor {
  size 100 100
}
Robot {
  translation 0 0.07999999999999997 0
  children [
    DEF SH_BODY Group {
      children [
        Shape {
          appearance PBRAppearance {
            baseColor 0.9372549019607843 0.1607843137254902 0.1607843137254902
            roughness 1
            metalness 0
          }
          geometry Box {
            size 0.25 0.08 0.1
          }
        }
        Transform {
          translation 0.1075 -0.0575 0
          children [
            Shape {
              appearance PBRAppearance {
                baseColor 0.9137254901960784 0.7254901960784313 0.43137254901960786
              }
              geometry Sphere {
                radius 0.0175
              }
            }
          ]
        }
      ]
    }
    HingeJoint {
      jointParameters HingeJointParameters {
        axis 0 0 1
        anchor -0.05 0 0.065
      }
      device [
        RotationalMotor {
          name "motor_right"
          maxVelocity 52.3598
          maxTorque 0.5931
        }
        PositionSensor {
          name "pos_right"
          resolution 0.0052359
        }
      ]
      endPoint Solid {
        translation -0.05 0 -0.06499952698969047
        rotation 1 0 0 1.5734979135770728
        children [
          DEF SH_WHEEL Shape {
            appearance DEF BLACK PBRAppearance {
              baseColor 0 0 0
              roughness 1
              metalness 0
            }
            geometry Cylinder {
              height 0.03
              radius 0.075
            }
          }
        ]
        boundingObject USE SH_WHEEL
        physics Physics {
        }
      }
    }
    HingeJoint {
      jointParameters HingeJointParameters {
        axis 0 0 1
        anchor -0.05 0 -0.065
      }
      device [
        RotationalMotor {
          name "motor_left"
          maxVelocity 52.3598
          maxTorque 0.5931
        }
        PositionSensor {
          name "pos_left"
          resolution 0.0052359
        }
      ]
      endPoint Solid {
        translation -0.05 0 0.065
        rotation 1 0 0 1.57
        children [
          USE SH_WHEEL
        ]
        name "solid(1)"
        boundingObject USE SH_WHEEL
        physics Physics {
        }
      }
    }
    DistanceSensor {
      translation 0.125 0 0
      children [
        DEF D_SENSOR Shape {
          appearance PBRAppearance {
          }
          geometry Box {
            size 0.01 0.01 0.01
          }
        }
      ]
      name "distance_sensor"
      lookupTable [
        0 0 0
        0.02 0 0
        5 1660 0
      ]
      resolution 1
    }
  ]
  boundingObject USE SH_BODY
  physics Physics {
    density -1
    mass 1
  }
  controller "crazybot"
}
